Workbook

Sheet Export-Zusammenfassung
B3: Dieses Dokument wurde aus Numbers exportiert und jede Tabelle in ein Excel-Arbeitsblatt umgewandelt. Alle anderen Objekte der einzelnen Numbers-Blätter wurden auf eigene Arbeitsblätter übertragen. Beachte, dass die Formelberechnungen in Excel möglicherweise anders sind.
B7: Name des Numbers-Blatts | C7: Numbers-Tabellenname | D7: Name des Excel-Arbeitsblatts
B9: Bilanz
C10: Tabelle 1 | D10: Bilanz
B11: GuV
C12: Tabelle 1 | D12: GuV
B13: Kennzahlen & Rechner
C14: Tabelle 1 | D14: Kennzahlen & Rechner
B15: Anhang & Checkliste
C16: Tabelle 1 | D16: Anhang & Checkliste

Sheet Bilanz
A1: JAHRESABSCHLUSS VORLAGE – BILANZ (§ 266 HGB)
A2: Stichtagsbetrachtung zum 31.12. | Angaben in EUR
C3: Geschäftsjahr | D3: Vorjahr | H3: Geschäftsjahr | I3: Vorjahr
C4: 2025 | D4: 2024 | H4: 2025 | I4: 2024
A5: A K T I V A (Mittelverwendung) | F5: P A S S I V A (Mittelherkunft)
A6: A. ANLAGEVERMÖGEN | F6: A. EIGENKAPITAL
A7: I. Immaterielle Vermögensgegenstände | C7: 85000 | D7: 50000 | F7: I. Gezeichnetes Kapital (Stammkapital) | H7: 25000 | I7: 25000
A8: II. Sachanlagen | C8: 42000 | D8: 28000 | F8: II. Kapitalrücklage | H8: 400000 | I8: 100000
A9: davon: Grundstücke & Gebäude | C9: 0 | D9: 0 | F9: III. Gewinnrücklagen | H9: 28000 | I9: 0
A10: davon: Technische Anlagen & Maschinen | C10: 0 | D10: 0 | F10: IV. Gewinn-/Verlustvortrag | H10: 432000 | I10: 246000
A11: davon: Betriebs- & Geschäftsausstattung | C11: 0 | D11: 0 | F11: V. Jahresüberschuss / Jahresfehlbetrag | H11: -215000 | I11: -23000
A12: III. Finanzanlagen | C12: 0 | D12: 0 | F12: Summe Eigenkapital | H12: 0 | I12: 0
A13: Summe Anlagevermögen | C13: {=C7+C8+C12} -> 320000 | D13: {=D7+D8+D12} -> 360000 | F13: B. RÜCKSTELLUNGEN
A14: B. UMLAUFVERMÖGEN | F14: Pensionsrückstellungen | H14: 45000 | I14: 28000
A15: I. Vorräte | C15: 0 | D15: 0 | F15: Steuerrückstellungen | H15: 0 | I15: 0
A16: II. Forderungen & sonstige Vermögensgegenstände | C16: 210000 | D16: 145000 | F16: Sonstige Rückstellungen | H16: 0 | I16: 0
A17: davon: Forderungen aus Lieferungen & Leistungen | C17: 0 | D17: 0 | F17: Summe Rückstellungen | H17: {=H14+H15+H16} -> 60000 | I17: {=I14+I15+I16} -> 52000
A18: davon: Sonstige Forderungen | C18: 1240000 | D18: 680000 | F18: C. VERBINDLICHKEITEN
A19: III. Wertpapiere (Umlaufvermögen) | C19: 0 | D19: 0 | F19: Verbindlichkeiten ggü. Kreditinstituten | H19: 0 | I19: 0
A20: IV. Kassenbestand, Bankguthaben & Schecks | C20: 0 | D20: 0 | F20: Verbindlichkeiten aus Lieferungen & Leistungen | H20: 185000 | I20: 98000
A21: Summe Umlaufvermögen | C21: {=C15+C16+C19+C20} -> 290000 | D21: {=D15+D16+D19+D20} -> 245000 | F21: Sonstige Verbindlichkeiten | H21: 695000 | I21: 441000
A22: C. RECHNUNGSABGRENZUNGSPOSTEN (ARAP) | C22: 18000 | D22: 12000 | F22: Summe Verbindlichkeiten | H22: {=H19+H20+H21} -> 140000 | I22: {=I19+I20+I21} -> 153000
A23: D. AKTIVE LATENTE STEUERN | C23: 0 | D23: 0 | F23: D. RECHNUNGSABGRENZUNGSPOSTEN (PRAP) | H23: 0 | I23: 0
A24: BILANZSUMME AKTIVA | C24: {=C13+C21+C22+C23} -> 620000 | D24: {=D13+D21+D22+D23} -> 613000 | F24: BILANZSUMME PASSIVA | H24: {=H12+H17+H22+H23} -> 520000 | I24: {=I12+I17+I22+I23} -> 475000
A25: PRÜFUNG BILANZGLEICHUNG: Aktiva GJ = Passiva GJ → Differenz: =C24-H24 | Vorjahr: =D24-I24
A26: Bilanzdifferenz Aktiva – Passiva (Geschäftsjahr): | E26: {=C24-H24} -> 100000
A28: Farblegende: Blau = Eingabewert (anpassbar) | Schwarz = Formel | Gelb = Pflichtfeld / Hinweis

Sheet GuV
A1: GEWINN- UND VERLUSTRECHNUNG (§ 275 HGB) – Gesamtkostenverfahren
A2: Periodenbetrachtung 01.01. – 31.12. | Angaben in EUR
C3: Geschäftsjahr | D3: Vorjahr
C4: 2025 | D4: 2024
A5: ERTRÄGE
A6: 1. Umsatzerlöse | C6: 2350000 | D6: 1702000
A7: 2. Erhöhung/Minderung des Bestands an fertigen und unfertigen Erzeugnissen | C7: 12000 | D7: 8000
A8: 3. Andere aktivierte Eigenleistungen | C8: 5000 | D8: 3000
A9: 4. Sonstige betriebliche Erträge | C9: 18000 | D9: 14000
A10: Gesamtleistung (1+2+3+4) | C10: {=C6+C7+C8+C9} -> 872000 | D10: {=D6+D7+D8+D9} -> 736500
A11: AUFWENDUNGEN
A12: 5. Materialaufwand | C12: 485000 | D12: 368000
A13: 6. Personalaufwand | C13: 890000 | D13: 640000
A14: a) Löhne & Gehälter | C14: 127000 | D14: 98000
A15: b) Soziale Abgaben & Aufwendungen für Altersversorgung | C15: 185000 | D15: 142000
A16: 7. Abschreibungen (AfA) | C16: 95000 | D16: 78000
A17: 8. Sonstige betriebliche Aufwendungen | C17: 72000 | D17: 55000
A18: Summe Betrieblicher Aufwand (5+6+7+8) | C18: {=C12+C13+C16+C17} -> 695000 | D18: {=D12+D13+D16+D17} -> 610000
A19: BETRIEBSERGEBNIS (EBIT) | C19: {=C10-C18} -> 177000 | D19: {=D10-D18} -> 126500
A20: FINANZERGEBNIS
A21: 10. Erträge aus Beteiligungen & Wertpapieren | C21: 8000 | D21: 3000
A22: 11. Zinsen und ähnliche Erträge | C22: 2000 | D22: 1500
A23: 12. Zinsen und ähnliche Aufwendungen | C23: 0 | D23: 0
A24: Finanzergebnis (10+11-12) | C24: {=C21+C22-C23} -> -4000 | D24: {=D21+D22-D23} -> -6200
A25: ERGEBNIS DER GEWÖHNLICHEN GESCHÄFTSTÄTIGKEIT | C25: {=C19+C24} -> 173000 | D25: {=D19+D24} -> 120300
A26: STEUERN
A27: 13. Steuern vom Einkommen und vom Ertrag | C27: 101000 | D27: 70000
A28: 14. Sonstige Steuern | C28: 9000 | D28: 7000
A29: JAHRESÜBERSCHUSS / JAHRESFEHLBETRAG
A30: Hinweis: Der Jahresüberschuss ist in die Bilanz (Eigenkapital / Gewinnvortrag) zu übertragen.
A32: Farblegende: Blau = Eingabewert (anpassbar) | Schwarz = Formel | Gelb = Pflichtfeld / Hinweis

Sheet Kennzahlen & Rechner
A1: BILANZKENNZAHLEN & BILANZ-STRUKTUR-RECHNER
A2: Automatisch verknüpft mit Bilanz & GuV | Eingaben in Blau, Formeln in Schwarz
A3: 1. VERKNÜPFTE BILANZKENNZAHLEN (Werte aus Bilanz & GuV)
A4: Kennzahl | B4: Geschäftsjahr | C4: Vorjahr | D4: Benchmark / Richtwert | E4: Bewertung
A5: Bilanzsumme (EUR) | B5: {='Bilanz'!C24} -> 620000 | C5: {='Bilanz'!D24} -> 613000 | D5: —
A6: Eigenkapital (EUR) | B6: {='Bilanz'!H12} -> 320000 | C6: {='Bilanz'!I12} -> 270000 | D6: —
A7: Fremdkapital (EUR) | B7: {='Bilanz'!H17+'Bilanz'!H22} -> 200000 | C7: {='Bilanz'!I17+'Bilanz'!I22} -> 205000 | D7: —
A8: Eigenkapitalquote (%) | B8: {='Bilanz'!H12/'Bilanz'!H24} -> 0.61538462 | C8: {='Bilanz'!I12/'Bilanz'!I24} -> 0.56842105 | D8: 20 % – 30 % (Mittelstand) | E8: EK-Quote > 30%: stabil | 20-30%: akzeptabel | < 20%: kritisch
A9: Fremdkapitalquote (%) | B9: {=('Bilanz'!H17+'Bilanz'!H22)/'Bilanz'!H24} -> 0.38461538 | C9: {=('Bilanz'!I17+'Bilanz'!I22)/'Bilanz'!I24} -> 0.43157895 | D9: < 70 %
A10: Anlagenintensität (%) | B10: {='Bilanz'!C13/'Bilanz'!C24} -> 0.51612903 | C10: {='Bilanz'!D13/'Bilanz'!D24} -> 0.58727569 | D10: Branchenabhängig
A11: Liquidität 1. Grades – Barliquidität (%) | B11: {='Bilanz'!C20/'Bilanz'!H22*100} -> 64.285714 | C11: {='Bilanz'!D20/'Bilanz'!I22*100} -> 39.215686 | D11: > 20 %
A12: Liquidität 2. Grades – Einzugsliquidität (%) | B12: {=('Bilanz'!C20+'Bilanz'!C16)/'Bilanz'!H22*100} -> 150 | C12: {=('Bilanz'!D20+'Bilanz'!D16)/'Bilanz'!I22*100} -> 111.11111 | D12: > 100 % | E12: < 100 %: potenzielle Liquiditätsprobleme
A13: Verschuldungsgrad (Fremdkap. / Eigenkapital) | B13: {=('Bilanz'!H17+'Bilanz'!H22)/'Bilanz'!H12} -> 0.625 | C13: {=('Bilanz'!I17+'Bilanz'!I22)/'Bilanz'!I12} -> 0.75925926 | D13: < 2,0x | E13: < 1x: sehr gut | 1-2x: ok | > 2x: risikoreich
A14: Umsatzerlöse (EUR) | B14: {='GuV'!C6} -> 850000 | C14: {='GuV'!D6} -> 720000 | D14: —
A15: EBIT (EUR) | B15: {='GuV'!C19} -> 177000 | C15: {='GuV'!D19} -> 126500 | D15: > 0
A16: EBIT-Marge (%) | B16: {='GuV'!C19/'GuV'!C6} -> 0.20823529 | C16: {='GuV'!D19/'GuV'!D6} -> 0.17569444 | D16: > 5 % | E16: Positives EBIT ist Mindestanforderung
A17: Jahresüberschuss (EUR) | B17: {='GuV'!C30} | C17: {='GuV'!D30} | D17: > 0 | E17: Positiv = Gewinn | Negativ = Fehlbetrag
A18: Umsatzrentabilität (%) | B18: {='GuV'!C30/'GuV'!C6} | C18: {='GuV'!D30/'GuV'!D6} | D18: > 3 %
A19: Eigenkapitalrentabilität (%) | B19: {='GuV'!C30/'Bilanz'!H12} | C19: {='GuV'!D30/'Bilanz'!I12} | D19: > 8 %
A20: Gesamtkapitalrentabilität (%) | B20: {=('GuV'!C30+'GuV'!C23)/'Bilanz'!H24} | C20: {=('GuV'!D30+'GuV'!D23)/'Bilanz'!I24} | D20: > 5 %
A23: 2. INTERAKTIVER BILANZ-STRUKTUR-RECHNER (unabhängige Eingabe)
A24: Geben Sie Ihre aggregierten Bilanzzahlen ein, um sofort zu prüfen, ob Ihre Bilanz ausgeglichen ist und wie Ihre Eigenkapitalquote ausfällt.
A25: AKTIVA
A26: Anlagevermögen (EUR) | B26: 320000
A27: Umlaufvermögen (EUR) | B27: 80000
A28: PASSIVA
A29: Eigenkapital (EUR) | B29: 120000
A30: Fremdkapital & Rückstellungen (EUR) | B30: 280000
A32: ERGEBNIS-CHECK
A33: Bilanzsumme Aktiva (EUR) | B33: {=B26+B27} -> 400000
A34: Bilanzsumme Passiva (EUR) | B34: {=B29+B30} -> 400000
A35: Differenz (Aktiva – Passiva) | B35: {=(B26+B27)-(B29+B30)} -> 0 | C35: {=IF((B26+B27)=(B29+B30),"Ausgeglichen","UNAUSGEGLICHEN – bitte prüfen!")} -> Ausgeglichen
A36: Eigenkapitalquote (%) | B36: {=B29/(B29+B30)} -> 0.3 | C36: Zielwert: 20 % – 30 % (Mittelstand)
A37: Eigenkapital (EUR) | B37: {=B29} -> 120000
A38: Gesamtkapital (EUR) | B38: {=B29+B30} -> 400000
A41: 3. HÄUFIGE STOLPERSTEINE BEI DER JAHRESABSCHLUSS-ERSTELLUNG
A42: Stolperstein | B42: Erläuterung | C42: Risiko
A43: Rechnungsabgrenzungsposten (ARAP/PRAP) | B43: Abgrenzung periodenfremder Aufwendungen/Erträge – oft vergessen | C43: Hoch
A44: Unvollständige Rückstellungen | B44: Urlaub, ausstehende Rechnungen, drohende Verluste | C44: Hoch
A45: Fehlerhafte Abschreibungen (AfA) | B45: Korrekte Nutzungsdauer & Methode (linear/degressiv) prüfen | C45: Hoch
...

Sheet Anhang & Checkliste
A1: ANHANG, LAGEBERICHT & ABSCHLUSSPROZESS-CHECKLISTE
A2: Pflichtbestandteile nach HGB | Für GmbH, UG, AG
A4: ABSCHLUSSPROZESS – 3 PHASEN
A5: Phase | B5: Aufgabe | C5: Details / Hinweise | D5: Verantwortlich | E5: Status
A6: 1 | B6: Vorbereitende Abschlussbuchungen | C6: Abgrenzungen, Rückstellungen, Korrekturen | D6: Buchhalter/Steuerberater | E6: Offen
A7: 1 | B7: Inventur & Bewertung | C7: Bestandsaufnahme, Niederstwertprinzip anwenden | D7: Lager / Controlling | E7: Offen
A8: 1 | B8: Kontenabstimmung | C8: Debitoren, Kreditoren, Konten abstimmen | D8: Buchhalter | E8: Offen
A9: 2 | B9: Anlagengitter & AfA-Berechnung | C9: Zugänge, Abgänge, Abschreibungen prüfen | D9: Controlling | E9: Offen
A10: 2 | B10: ARAP / PRAP buchen | C10: Periodenabgrenzung sicherstellen | D10: Buchhalter | E10: Offen
A11: 2 | B11: Rückstellungen bilden | C11: Urlaub, ausstehende Rechnungen, Garantien | D11: Buchhalter/Steuerberater | E11: Offen
A12: 3 | B12: Bilanz erstellen | C12: Gemäß § 266 HGB, Gliederung prüfen | D12: Steuerberater | E12: Offen
A13: 3 | B13: GuV erstellen | C13: Gemäß § 275 HGB, GKV oder UKV | D13: Steuerberater | E13: Offen
A14: 3 | B14: Anhang verfassen | C14: Pflicht für Kapitalgesellschaften (außer Kleinstkapitalges.) | D14: Steuerberater | E14: Offen
A15: 3 | B15: Lagebericht erstellen | C15: Pflicht ab mittlerer GmbH / AG | D15: Management / Steuerberater | E15: Offen
A16: 3 | B16: Feststellung & Offenlegung | C16: Bundesanzeiger / Handelsregister | D16: Geschäftsführung | E16: Offen
A19: PFLICHTINHALTE DES ANHANGS (§ 284 – 288 HGB)
A20: Nr. | B20: Anhangspunkt | C20: Hinweis / Details | D20: Relevanz | E20: Erledigt
A21: 1 | B21: Bilanzierungs- und Bewertungsmethoden | C21: Welche Methoden wurden angewendet? Abweichungen begründen | D21: Pflicht
A22: 2 | B22: Angaben zu Abschreibungen | C22: Methode, Nutzungsdauer, außerplanmäßige Abschreibungen | D22: Pflicht
A23: 3 | B23: Angaben zu Verbindlichkeiten (Fristigkeit) | C23: Restlaufzeiten < 1 Jahr, 1–5 Jahre, > 5 Jahre | D23: Pflicht
A24: 4 | B24: Angaben zu Haftungsverhältnissen | C24: Bürgschaften, Garantien, Eventualverbindlichkeiten | D24: Pflicht
A25: 5 | B25: Angaben zu Organen der Gesellschaft | C25: Geschäftsführer / Vorstand / Aufsichtsrat | D25: GmbH/AG Pflicht
A26: 6 | B26: Durchschnittliche Arbeitnehmerzahl | C26: Im Geschäftsjahr beschäftigte Mitarbeiter | D26: Pflicht
A27: 7 | B27: Angaben zu außergewöhnlichen Vorgängen | C27: Wesentliche Ereignisse nach Bilanzstichtag | D27: Pflicht
A28: 8 | B28: Angaben zum Konsolidierungskreis | C28: Bei Konzernabschluss: Tochtergesellschaften | D28: Ggf. Pflicht
A31: FORMELREFERENZ – EIGENKAPITALQUOTE
A32: Formel: | B32: Eigenkapitalquote (%) = Eigenkapital / Gesamtkapital × 100
A33: Eigenkapital: | B33: Mittel der Eigentümer + im Unternehmen verbliebene Gewinne
A34: Gesamtkapital: | B34: Eigenkapital + Fremdkapital = Bilanzsumme
A35: Benchmark: | B35: Gesund: 20–30 % | Kritisch: < 20 % | Sehr gut: > 30 %
A36: Quelle: | B36: § 266, § 275 HGB | Automatisch berechnet auf Sheet 'Kennzahlen & Rechner'
A38: Farblegende: Phase 1 = Blau | Phase 2 = Grün | Phase 3 = Gelb | Pflicht = Mindestanforderung HGB
